<?xml version="1.0"?>

<robot xmlns:xacro="http://ros.org/wiki/xacro">
  <!-- Macro for the inertia of a box -->
  <xacro:macro name="box_inertia" params="x y z mass">
    <inertia ixx="${0.0833333 * mass * (y*y + z*z)}" ixy="0.0" ixz="0.0"
      iyy="${0.0833333 * mass * (x*x + z*z)}" iyz="0.0"
      izz="${0.0833333 * mass * (x*x + y*y)}" />
  </xacro:macro>

  <!-- Macro for the inertial properties of a box -->
  <xacro:macro name="box_inertial" params="x y z mass *origin">
    <inertial>
      <mass value="${mass}" />
      <xacro:insert_block name="origin" />
      <xacro:box_inertia x="${x}" y="${y}" z="${z}" mass="${mass}" />
    </inertial>
  </xacro:macro>

  <!-- Rotor Joint and Link -->
   <xacro:macro name="simple_rotor"
    params="namespace parent command_topic direction force_constant torque_constant mass_rotor radius_rotor motor_number color use_own_mesh mesh *origin *inertia">
    <joint name="${namespace}/rotor_${motor_number}_joint" type="continuous">
      <xacro:insert_block name="origin" />
      <axis xyz="0 0 1" />
      <parent link="${parent}" />
      <child link="${namespace}/rotor_${motor_number}" />
    </joint>
    <link name="${namespace}/rotor_${motor_number}">
      <inertial>
        <mass value="${mass_rotor}" /> <!-- [kg] -->
        <xacro:insert_block name="inertia" />
      </inertial>
      <visual>
        <geometry>
          <xacro:if value="${use_own_mesh}">
            <mesh filename="${mesh}"
              scale="1 1 1" />
          </xacro:if>
          <xacro:unless value="${use_own_mesh}">
            <mesh filename="package://fcu_sim/meshes/propeller_${direction}.dae"
              scale="${radius_rotor} ${radius_rotor} ${radius_rotor}" />
          </xacro:unless>
        </geometry>
      </visual>
      <collision>
        <geometry>
          <cylinder length="0.005" radius="${radius_rotor}" /> 
        </geometry>
      </collision>
    </link>

    <gazebo>
      <plugin name="${namespace}_motor_${motor_number}" filename="libsimple_rotor_plugin.so">
        <namespace>${namespace}</namespace>
        <jointName>${namespace}/rotor_${motor_number}_joint</jointName>
        <linkName>${namespace}/rotor_${motor_number}</linkName>
        <motorDirection>${direction}</motorDirection>
        <motorNumber>${motor_number}</motorNumber>
        <k_force>${force_constant}</k_force>
        <k_torque>${torque_constant}</k_torque>
        <commandTopic>${command_topic}</commandTopic>
      </plugin>
    </gazebo>
    <gazebo reference="${namespace}/motor_${motor_number}">
      <material>Gazebo/${color}</material>
    </gazebo>
  </xacro:macro>


</robot>
